<?xml version="1.0" encoding="utf-8"?>
<!-- =================================================================================== -->
<!-- |    This document was autogenerated by xacro from /home/iti0201/catkin_ws/src/pibot_description/models/iti0201_robot/urdf/generate_pibot.urdf.xacro | -->
<!-- |    EDITING THIS FILE BY HAND IS NOT RECOMMENDED                                 | -->
<!-- =================================================================================== -->
<robot name="pibot" xmlns:xacro="http://www.ros.org/wiki/xacro">
  <link name="base_with_casters">
    <inertial>
      <mass value="5"/>
      <inertia ixx="0.0061259375" ixy="0.0" ixz="0.0" iyy="0.0061259375" iyz="0.0" izz="0.01225"/>
    </inertial>
    <visual name="base_visual">
      <origin rpy="0 0 -1.57" xyz="-0.09 0.098 0.005"/>
      <geometry>
        <mesh filename="model://iti0201_robot/meshes/pibot2_base.dae"/>
        <!--cylinder length="0.0015" radius="0.07"/-->
      </geometry>
    </visual>
    <collision name="base_collision">
      <origin rpy="0 0 -1.57" xyz="-0.09 0.098 0.005"/>
      <geometry>
        <mesh filename="model://iti0201_robot/meshes/pibot2_base.dae"/>
        <!--cylinder length="0.0015" radius="0.07"/-->
      </geometry>
    </collision>
    <visual name="front_caster_visual">
      <origin rpy="0 0 0" xyz="0.04 0 0.005"/>
      <geometry>
        <sphere radius="0.005"/>
      </geometry>
    </visual>
    <collision name="front_caster_collision">
      <origin rpy="0 0 0" xyz="0.04 0 0.005"/>
      <geometry>
        <sphere radius="0.005"/>
      </geometry>
    </collision>
  </link>
  <gazebo reference="base_with_casters">
    <surface>
      <friction>
        <ode>
          <mu>0</mu>
          <mu2>0</mu2>
          <slip1>1.0</slip1>
          <slip2>1.0</slip2>
        </ode>
      </friction>
    </surface>
  </gazebo>
  <link name="wheel_joint">
    <inertial>
      <mass value="0.001"/>
      <inertia ixx="1.66666666667e-10" ixy="0.0" ixz="0.0" iyy="1.66666666667e-10" iyz="0.0" izz="1.66666666667e-10"/>
    </inertial>
    <visual name="joint_visual">
      <geometry>
        <box size="0.001 0.001 0.001"/>
      </geometry>
    </visual>
  </link>
  <joint name="Wheel_joint_to_base" type="fixed">
    <origin rpy="0 0 0" xyz="-0.0295 0 0.015"/>
    <child link="wheel_joint"/>
    <parent link="base_with_casters"/>
  </joint>
  <link name="right_wheel">
    <inertial>
      <mass value="1"/>
      <inertia ixx="6.3e-05" ixy="0.0" ixz="0.0" iyy="6.3e-05" iyz="0.0" izz="0.0001125"/>
    </inertial>
    <visual name="right_wheel_visual">
      <origin rpy="0 0 0" xyz="0 0 0"/>
      <geometry>
        <cylinder length="0.009" radius="0.015"/>
      </geometry>
    </visual>
    <collision name="right_wheel_collision">
      <origin rpy="0 0 0" xyz="0 0 0"/>
      <geometry>
        <cylinder length="0.009" radius="0.015"/>
      </geometry>
    </collision>
  </link>
  <gazebo reference="right_wheel">
    <mu1 value="1.0"/>
    <mu2 value="1.0"/>
    <kp value="10000000.0"/>
    <kd value="1.0"/>
    <fdir1 value="1 0 0"/>
  </gazebo>
  <joint name="right_wheel_hinge" type="continuous">
    <origin rpy="0 1.5707 1.5707" xyz="0 -0.0655 0"/>
    <child link="right_wheel"/>
    <parent link="wheel_joint"/>
    <!--proovisin erinevaid väärtusi siia "limit" alla, midagi ei muutunud -->
    <limit effort="10.0" velocity="1.0"/>
    <axis rpy="0 0 0" xyz="0 0 1"/>
  </joint>
  <link name="left_wheel">
    <inertial>
      <mass value="1"/>
      <inertia ixx="6.3e-05" ixy="0.0" ixz="0.0" iyy="6.3e-05" iyz="0.0" izz="0.0001125"/>
    </inertial>
    <visual name="left_wheel_visual">
      <origin rpy="0 0 0" xyz="0 0 0"/>
      <geometry>
        <cylinder length="0.009" radius="0.015"/>
      </geometry>
    </visual>
    <collision name="left_wheel_collision">
      <origin rpy="0 0 0" xyz="0 0 0"/>
      <geometry>
        <cylinder length="0.009" radius="0.015"/>
      </geometry>
    </collision>
  </link>
  <gazebo reference="left_wheel">
    <mu1 value="1.0"/>
    <mu2 value="1.0"/>
    <kp value="10000000.0"/>
    <kd value="1.0"/>
    <fdir1 value="1 0 0"/>
  </gazebo>
  <joint name="left_wheel_hinge" type="continuous">
    <origin rpy="0 1.5707 1.5707" xyz="0 0.0655 0"/>
    <child link="left_wheel"/>
    <parent link="wheel_joint"/>
    <limit effort="10.0" velocity="1.0"/>
    <axis rpy="0 0 0" xyz="0 0 1"/>
  </joint>
  <gazebo>
    <plugin filename="libwheel_plugin.so" name="wheel_plugin"/>
  </gazebo>
  <!--xacro:grabber_arm/-->
</robot>
