<?xml version="1.0" ?>
<!-- =================================================================================== -->
<!-- |    This document was autogenerated by xacro from /home/iti0201/catkin_ws/src/pibot_description/models/iti0201_robot/urdf/generate_pibot.urdf.xacro | -->
<!-- |    EDITING THIS FILE BY HAND IS NOT RECOMMENDED                                 | -->
<!-- =================================================================================== -->
<robot name="pibot">
  <gazebo>
    <plugin filename="libgazebo_ros_imu.so" name="imu_plugin">
      <alwaysOn>true</alwaysOn>
      <bodyName>base_with_casters</bodyName>
      <topicName>/robot/imu/raw</topicName>
      <gaussianNoise>0.0</gaussianNoise>
      <updateRate>10.0</updateRate>
    </plugin>
  </gazebo>
  <link name="base_with_casters">
    <inertial>
      <mass value="5"/>
      <inertia ixx="0.006125937500000001" ixy="0.0" ixz="0.0" iyy="0.006125937500000001" iyz="0.0" izz="0.012250000000000002"/>
    </inertial>
    <visual name="base_visual">
      <origin rpy="0 0 -1.57" xyz="-0.0615 0.098 0.005"/>
      <geometry>
        <mesh filename="model://iti0201_robot/meshes/pibot2_base.dae"/>
        <!--cylinder length="0.0015" radius="0.07"/-->
      </geometry>
    </visual>
    <collision name="base_collision">
      <origin rpy="0 0 -1.57" xyz="-0.0615 0.098 0.005"/>
      <geometry>
        <mesh filename="model://iti0201_robot/meshes/pibot2_base.dae"/>
        <!--cylinder length="0.0015" radius="0.07"/-->
      </geometry>
    </collision>
    <visual name="front_caster_visual">
      <origin rpy="0 0 0" xyz="0.04 0 0.005"/>
      <geometry>
        <sphere radius="0.005"/>
      </geometry>
    </visual>
    <collision name="front_caster_collision">
      <origin rpy="0 0 0" xyz="0.04 0 0.005"/>
      <geometry>
        <sphere radius="0.005"/>
      </geometry>
    </collision>
  </link>
  <gazebo reference="base_with_casters">
    <surface>
      <friction>
        <ode>
          <mu>0</mu>
          <mu2>0</mu2>
          <slip1>1.0</slip1>
          <slip2>1.0</slip2>
        </ode>
      </friction>
    </surface>
  </gazebo>
  <link name="wheel_joint">
    <inertial>
      <mass value="0.001"/>
      <inertia ixx="1.6666666666666666e-10" ixy="0.0" ixz="0.0" iyy="1.6666666666666666e-10" iyz="0.0" izz="1.6666666666666666e-10"/>
    </inertial>
    <visual name="joint_visual">
      <geometry>
        <box size="0.001 0.001 0.001"/>
      </geometry>
    </visual>
  </link>
  <joint name="Wheel_joint_to_base" type="fixed">
    <origin rpy="0 0 0" xyz="0 0 0.015"/>
    <child link="wheel_joint"/>
    <parent link="base_with_casters"/>
  </joint>
  <link name="brainbox_with_battery">
    <inertial>
      <mass value="0.001"/>
      <inertia ixx="8.833333333333333e-07" ixy="0.0" ixz="0.0" iyy="8.590833333333331e-07" iyz="0.0" izz="3.924166666666667e-07"/>
    </inertial>
    <visual name="brainbox_visual">
      <origin rpy="0 0 0" xyz="-0.022 0 0.0294"/>
      <geometry>
        <box size="0.077 0.0468 0.0512"/>
      </geometry>
    </visual>
    <visual name="camera_stand_visual">
      <origin rpy="0 0 0" xyz="0.0294 0 0.043"/>
      <geometry>
        <box size="0.0255 0.0553 0.07896"/>
      </geometry>
    </visual>
    <visual name="camera_stand_right_wall_visual">
      <origin rpy="0 0 0" xyz="0.0294 -0.02467 0.1"/>
      <geometry>
        <box size="0.0255 0.006 0.0346"/>
      </geometry>
    </visual>
    <visual name="camera_stand_left_wall_visual">
      <origin rpy="0 0 0" xyz="0.0294 0.02467 0.1"/>
      <geometry>
        <box size="0.0255 0.006 0.0346"/>
      </geometry>
    </visual>
  </link>
  <joint name="brainbox_to_base" type="fixed">
    <origin rpy="0 0 0" xyz="0.0285 0 0.003"/>
    <child link="brainbox_with_battery"/>
    <parent link="base_with_casters"/>
  </joint>
  <link name="front_right_45deg_ir">
    <inertial>
      <mass value="0.001"/>
      <inertia ixx="4.166666666666667e-08" ixy="0.0" ixz="0.0" iyy="1.6666666666666667e-08" iyz="0.0" izz="4.166666666666667e-08"/>
    </inertial>
    <collision name="front_right_45deg_ir_collision">
      <geometry>
        <box size="0.01 0.01 0.02"/>
      </geometry>
    </collision>
    <visual name="front_right_45deg_ir_visual">
      <geometry>
        <box size="0.01 0.01 0.02"/>
      </geometry>
    </visual>
  </link>
  <joint name="front_right_45deg_ir_to_base" type="fixed">
    <origin rpy="0 0 -0.78535" xyz="0.0611 -0.0471 0.016"/>
    <child link="front_right_45deg_ir"/>
    <parent link="base_with_casters"/>
  </joint>
  <gazebo reference="front_right_45deg_ir">
    <sensor name="ir" type="ray">
      <ray>
        <scan>
          <horizontal>
            <samples>1</samples>
            <resolution>1</resolution>
          </horizontal>
        </scan>
        <range>
          <min>0.05</min>
          <max>2.00</max>
          <resolution>0.01</resolution>
        </range>
      </ray>
      <always_on>1</always_on>
      <update_rate>10</update_rate>
      <visualize>false</visualize>
      <plugin filename="libir_plugin.so" name="ir_plugin">
        <topic>ir/front_right</topic>
      </plugin>
    </sensor>
  </gazebo>
  <link name="front_middle_ir">
    <inertial>
      <mass value="0.001"/>
      <inertia ixx="1.6666666666666667e-08" ixy="0.0" ixz="0.0" iyy="4.166666666666667e-08" iyz="0.0" izz="4.166666666666667e-08"/>
    </inertial>
    <collision name="front_middle_ir_collision">
      <geometry>
        <box size="0.01 0.02 0.01"/>
      </geometry>
    </collision>
    <visual name="front_middle_ir_visual">
      <geometry>
        <box size="0.01 0.02 0.01"/>
      </geometry>
    </visual>
  </link>
  <joint name="front_middle_ir_to_base" type="fixed">
    <origin rpy="0 0 0" xyz="0.087812 0 0.011"/>
    <child link="front_middle_ir"/>
    <parent link="base_with_casters"/>
  </joint>
  <gazebo reference="front_middle_ir">
    <sensor name="ir" type="ray">
      <ray>
        <scan>
          <horizontal>
            <samples>1</samples>
            <resolution>1</resolution>
          </horizontal>
        </scan>
        <range>
          <min>0.05</min>
          <max>2.00</max>
          <resolution>0.01</resolution>
        </range>
      </ray>
      <always_on>1</always_on>
      <update_rate>10</update_rate>
      <visualize>false</visualize>
      <plugin filename="libir_plugin.so" name="ir_plugin">
        <topic>ir/front_middle</topic>
      </plugin>
    </sensor>
  </gazebo>
  <link name="front_left_45deg_ir">
    <inertial>
      <mass value="0.001"/>
      <inertia ixx="4.166666666666667e-08" ixy="0.0" ixz="0.0" iyy="1.6666666666666667e-08" iyz="0.0" izz="4.166666666666667e-08"/>
    </inertial>
    <collision name="front_left_45deg_ir_collisionl">
      <geometry>
        <box size="0.01 0.01 0.02"/>
      </geometry>
    </collision>
    <visual name="front_left_45deg_ir_visual">
      <geometry>
        <box size="0.01 0.01 0.02"/>
      </geometry>
    </visual>
  </link>
  <joint name="front_left_45deg_ir_to_base" type="fixed">
    <origin rpy="0 0 0.78535" xyz="0.0611151 0.0470558 0.016"/>
    <child link="front_left_45deg_ir"/>
    <parent link="base_with_casters"/>
  </joint>
  <gazebo reference="front_left_45deg_ir">
    <sensor name="ir" type="ray">
      <ray>
        <scan>
          <horizontal>
            <samples>1</samples>
            <resolution>1</resolution>
          </horizontal>
        </scan>
        <range>
          <min>0.05</min>
          <max>2.00</max>
          <resolution>0.01</resolution>
        </range>
      </ray>
      <always_on>1</always_on>
      <update_rate>10</update_rate>
      <visualize>false</visualize>
      <plugin filename="libir_plugin.so" name="ir_plugin">
        <topic>ir/front_left</topic>
      </plugin>
    </sensor>
  </gazebo>
  <link name="rear_right_90deg_ir">
    <inertial>
      <mass value="0.001"/>
      <inertia ixx="2.7187499999999998e-08" ixy="0.0" ixz="0.0" iyy="1.7333333333333333e-08" iyz="0.0" izz="2.052083333333333e-08"/>
    </inertial>
    <collision name="collision">
      <geometry>
        <box size="0.012 0.008 0.0135"/>
      </geometry>
    </collision>
    <visual name="visual">
      <geometry>
        <box size="0.012 0.008 0.0135"/>
      </geometry>
    </visual>
  </link>
  <joint name="rear_right_90deg_ir_to_base" type="fixed">
    <origin rpy="0 0 -1.5707" xyz="-0.0215 -0.058 0.013"/>
    <child link="rear_right_90deg_ir"/>
    <parent link="base_with_casters"/>
  </joint>
  <gazebo reference="rear_right_90deg_ir">
    <sensor name="ir" type="ray">
      <ray>
        <scan>
          <horizontal>
            <samples>1</samples>
            <resolution>1</resolution>
          </horizontal>
        </scan>
        <range>
          <min>0.01</min>
          <max>0.40</max>
          <resolution>0.01</resolution>
        </range>
      </ray>
      <always_on>1</always_on>
      <update_rate>10</update_rate>
      <visualize>false</visualize>
      <plugin filename="libir_plugin.so" name="ir_plugin">
        <topic>ir/rear_right_90</topic>
      </plugin>
    </sensor>
  </gazebo>
  <link name="rear_right_45deg_ir">
    <inertial>
      <mass value="0.001"/>
      <inertia ixx="2.7187499999999998e-08" ixy="0.0" ixz="0.0" iyy="1.7333333333333333e-08" iyz="0.0" izz="2.052083333333333e-08"/>
    </inertial>
    <collision name="collision">
      <geometry>
        <box size="0.012 0.008 0.0135"/>
      </geometry>
    </collision>
    <visual name="visual">
      <geometry>
        <box size="0.012 0.008 0.0135"/>
      </geometry>
    </visual>
  </link>
  <joint name="rear_right_45deg_ir_to_base" type="fixed">
    <origin rpy="0 0 -2.35605" xyz="-0.03 -0.045 0.013"/>
    <child link="rear_right_45deg_ir"/>
    <parent link="base_with_casters"/>
  </joint>
  <gazebo reference="rear_right_45deg_ir">
    <sensor name="ir" type="ray">
      <ray>
        <scan>
          <horizontal>
            <samples>1</samples>
            <resolution>1</resolution>
          </horizontal>
        </scan>
        <range>
          <min>0.01</min>
          <max>0.40</max>
          <resolution>0.01</resolution>
        </range>
      </ray>
      <always_on>1</always_on>
      <update_rate>10</update_rate>
      <visualize>false</visualize>
      <plugin filename="libir_plugin.so" name="ir_plugin">
        <topic>ir/rear_right_45</topic>
      </plugin>
    </sensor>
  </gazebo>
  <link name="rear_right_straight_ir">
    <inertial>
      <mass value="0.001"/>
      <inertia ixx="2.7187499999999998e-08" ixy="0.0" ixz="0.0" iyy="1.7333333333333333e-08" iyz="0.0" izz="2.052083333333333e-08"/>
    </inertial>
    <collision name="collision">
      <geometry>
        <box size="0.012 0.008 0.0135"/>
      </geometry>
    </collision>
    <visual name="visual">
      <geometry>
        <box size="0.012 0.008 0.0135"/>
      </geometry>
    </visual>
  </link>
  <joint name="rear_right_straight_ir_to_base" type="fixed">
    <origin rpy="0 0 -3.14" xyz="-0.0315 -0.03 0.013"/>
    <child link="rear_right_straight_ir"/>
    <parent link="base_with_casters"/>
  </joint>
  <gazebo reference="rear_right_straight_ir">
    <sensor name="ir" type="ray">
      <ray>
        <scan>
          <horizontal>
            <samples>1</samples>
            <resolution>1</resolution>
          </horizontal>
        </scan>
        <range>
          <min>0.01</min>
          <max>0.40</max>
          <resolution>0.01</resolution>
        </range>
      </ray>
      <always_on>1</always_on>
      <update_rate>10</update_rate>
      <visualize>false</visualize>
      <plugin filename="libir_plugin.so" name="ir_plugin">
        <topic>ir/rear_right_0</topic>
      </plugin>
    </sensor>
  </gazebo>
  <link name="rear_left_90deg_ir">
    <inertial>
      <mass value="0.001"/>
      <inertia ixx="2.7187499999999998e-08" ixy="0.0" ixz="0.0" iyy="1.7333333333333333e-08" iyz="0.0" izz="2.052083333333333e-08"/>
    </inertial>
    <collision name="collision">
      <geometry>
        <box size="0.012 0.008 0.0135"/>
      </geometry>
    </collision>
    <visual name="visual">
      <geometry>
        <box size="0.012 0.008 0.0135"/>
      </geometry>
    </visual>
  </link>
  <joint name="rear_left_90deg_ir_to_base" type="fixed">
    <origin rpy="0 0 1.5707" xyz="-0.0215 0.058 0.013"/>
    <child link="rear_left_90deg_ir"/>
    <parent link="base_with_casters"/>
  </joint>
  <gazebo reference="rear_left_90deg_ir">
    <sensor name="ir" type="ray">
      <ray>
        <scan>
          <horizontal>
            <samples>1</samples>
            <resolution>1</resolution>
          </horizontal>
        </scan>
        <range>
          <min>0.01</min>
          <max>0.40</max>
          <resolution>0.01</resolution>
        </range>
      </ray>
      <always_on>1</always_on>
      <update_rate>10</update_rate>
      <visualize>false</visualize>
      <plugin filename="libir_plugin.so" name="ir_plugin">
        <topic>ir/rear_left_90</topic>
      </plugin>
    </sensor>
  </gazebo>
  <link name="rear_left_45deg_ir">
    <inertial>
      <mass value="0.001"/>
      <inertia ixx="2.7187499999999998e-08" ixy="0.0" ixz="0.0" iyy="1.7333333333333333e-08" iyz="0.0" izz="2.052083333333333e-08"/>
    </inertial>
    <collision name="collision">
      <geometry>
        <box size="0.012 0.008 0.0135"/>
      </geometry>
    </collision>
    <visual name="visual">
      <geometry>
        <box size="0.012 0.008 0.0135"/>
      </geometry>
    </visual>
  </link>
  <joint name="rear_left_45deg_ir_to_base" type="fixed">
    <origin rpy="0 0 2.35605" xyz="-0.03 0.045 0.013"/>
    <child link="rear_left_45deg_ir"/>
    <parent link="base_with_casters"/>
  </joint>
  <gazebo reference="rear_left_45deg_ir">
    <sensor name="ir" type="ray">
      <ray>
        <scan>
          <horizontal>
            <samples>1</samples>
            <resolution>1</resolution>
          </horizontal>
        </scan>
        <range>
          <min>0.01</min>
          <max>0.40</max>
          <resolution>0.01</resolution>
        </range>
      </ray>
      <always_on>1</always_on>
      <update_rate>10</update_rate>
      <visualize>false</visualize>
      <plugin filename="libir_plugin.so" name="ir_plugin">
        <topic>ir/rear_left_45</topic>
      </plugin>
    </sensor>
  </gazebo>
  <link name="rear_left_straight_ir">
    <inertial>
      <mass value="0.001"/>
      <inertia ixx="2.7187499999999998e-08" ixy="0.0" ixz="0.0" iyy="1.7333333333333333e-08" iyz="0.0" izz="2.052083333333333e-08"/>
    </inertial>
    <collision name="collision">
      <geometry>
        <box size="0.012 0.008 0.0135"/>
      </geometry>
    </collision>
    <visual name="visual">
      <geometry>
        <box size="0.012 0.008 0.0135"/>
      </geometry>
    </visual>
  </link>
  <joint name="rear_left_straight_ir_to_base" type="fixed">
    <origin rpy="0 0 3.14" xyz="-0.0315 0.03 0.013"/>
    <child link="rear_left_straight_ir"/>
    <parent link="base_with_casters"/>
  </joint>
  <gazebo reference="rear_left_straight_ir">
    <sensor name="ir" type="ray">
      <pose>0 0 0 0 -0 1.571</pose>
      <ray>
        <scan>
          <horizontal>
            <samples>1</samples>
            <resolution>1</resolution>
          </horizontal>
        </scan>
        <range>
          <min>0.01</min>
          <max>0.40</max>
          <resolution>0.01</resolution>
        </range>
      </ray>
      <always_on>1</always_on>
      <update_rate>10</update_rate>
      <visualize>false</visualize>
      <plugin filename="libir_plugin.so" name="ir_plugin">
        <topic>ir/rear_left_0</topic>
      </plugin>
    </sensor>
  </gazebo>
  <link name="right_side_first_line_sensor_from_middle">
    <inertial>
      <mass value="0.001"/>
      <inertia ixx="1.5416666666666668e-09" ixy="0.0" ixz="0.0" iyy="1.2083333333333334e-09" iyz="0.0" izz="7.083333333333333e-10"/>
    </inertial>
    <collision name="collision">
      <geometry>
        <box size="0.0015 0.0035 0.0025"/>
      </geometry>
    </collision>
    <visual name="visual">
      <geometry>
        <box size="0.0015 0.0035 0.0025"/>
      </geometry>
    </visual>
  </link>
  <joint name="right_side_first_line_sensor_from_middle_to_base" type="fixed">
    <origin rpy="0 1.5707 0" xyz="0.0935 -0.005 0.0044"/>
    <child link="right_side_first_line_sensor_from_middle"/>
    <parent link="base_with_casters"/>
  </joint>
  <gazebo reference="right_side_first_line_sensor_from_middle">
    <sensor name="line_sensor_camera1" type="camera">
      <update_rate>10</update_rate>
      <camera name="head">
        <horizontal_fov>0.4</horizontal_fov>
        <image>
          <width>16</width>
          <height>16</height>
          <format>L8</format>
        </image>
        <clip>
          <near>0.001</near>
          <far>0.031</far>
        </clip>
      </camera>
      <always_on>1</always_on>
      <update_rate>10</update_rate>
      <visualize>false</visualize>
      <plugin filename="libgazebo_ros_camera.so" name="camera_controller">
        <alwaysOn>true</alwaysOn>
        <updateRate>10</updateRate>
        <cameraName>/robot/line_sensor/right_first</cameraName>
        <imageTopicName>image_raw</imageTopicName>
        <cameraInfoTopicName>camera_info</cameraInfoTopicName>
        <frameName>camera_link</frameName>
        <hackBaseline>0.07</hackBaseline>
        <distortionK1>0.0</distortionK1>
        <distortionK2>0.0</distortionK2>
        <distortionK3>0.0</distortionK3>
        <distortionT1>0.0</distortionT1>
        <distortionT2>0.0</distortionT2>
      </plugin>
    </sensor>
  </gazebo>
  <link name="left_side_first_line_sensor_from_middle">
    <inertial>
      <mass value="0.001"/>
      <inertia ixx="1.5416666666666668e-09" ixy="0.0" ixz="0.0" iyy="1.2083333333333334e-09" iyz="0.0" izz="7.083333333333333e-10"/>
    </inertial>
    <collision name="collision">
      <geometry>
        <box size="0.0015 0.0035 0.0025"/>
      </geometry>
    </collision>
    <visual name="visual">
      <geometry>
        <box size="0.0015 0.0035 0.0025"/>
      </geometry>
    </visual>
  </link>
  <joint name="left_side_first_line_sensor_from_middle_to_base" type="fixed">
    <origin rpy="0 1.5707 0" xyz="0.0935 0.005 0.0044"/>
    <child link="left_side_first_line_sensor_from_middle"/>
    <parent link="base_with_casters"/>
  </joint>
  <gazebo reference="left_side_first_line_sensor_from_middle">
    <sensor name="line_sensor_camera2" type="camera">
      <update_rate>10</update_rate>
      <pose>0 0 0 0 1.571 0</pose>
      <camera name="head">
        <horizontal_fov>0.4</horizontal_fov>
        <image>
          <width>16</width>
          <height>16</height>
          <format>L8</format>
        </image>
        <clip>
          <near>0.001</near>
          <far>0.031</far>
        </clip>
      </camera>
      <always_on>1</always_on>
      <update_rate>10</update_rate>
      <visualize>false</visualize>
      <plugin filename="libgazebo_ros_camera.so" name="camera_controller">
        <alwaysOn>true</alwaysOn>
        <updateRate>10</updateRate>
        <cameraName>/robot/line_sensor/left_first</cameraName>
        <imageTopicName>image_raw</imageTopicName>
        <cameraInfoTopicName>camera_info</cameraInfoTopicName>
        <frameName>camera_link</frameName>
        <hackBaseline>0.07</hackBaseline>
        <distortionK1>0.0</distortionK1>
        <distortionK2>0.0</distortionK2>
        <distortionK3>0.0</distortionK3>
        <distortionT1>0.0</distortionT1>
        <distortionT2>0.0</distortionT2>
      </plugin>
    </sensor>
  </gazebo>
  <link name="right_side_second_line_sensor_from_middle">
    <inertial>
      <mass value="0.001"/>
      <inertia ixx="1.5416666666666668e-09" ixy="0.0" ixz="0.0" iyy="1.2083333333333334e-09" iyz="0.0" izz="7.083333333333333e-10"/>
    </inertial>
    <collision name="collision">
      <geometry>
        <box size="0.0015 0.0035 0.0025"/>
      </geometry>
    </collision>
    <visual name="visual">
      <geometry>
        <box size="0.0015 0.0035 0.0025"/>
      </geometry>
    </visual>
  </link>
  <joint name="right_side_second_line_sensor_from_middle_to_base" type="fixed">
    <origin rpy="0 1.5707 0" xyz="0.0935 -0.015 0.0044"/>
    <child link="right_side_second_line_sensor_from_middle"/>
    <parent link="base_with_casters"/>
  </joint>
  <gazebo reference="right_side_second_line_sensor_from_middle">
    <sensor name="line_sensor_camera3" type="camera">
      <update_rate>10</update_rate>
      <pose>0 0 0 0 1.571 0</pose>
      <camera name="head">
        <horizontal_fov>0.4</horizontal_fov>
        <image>
          <width>16</width>
          <height>16</height>
          <format>L8</format>
        </image>
        <clip>
          <near>0.001</near>
          <far>0.031</far>
        </clip>
      </camera>
      <always_on>1</always_on>
      <update_rate>10</update_rate>
      <visualize>false</visualize>
      <plugin filename="libgazebo_ros_camera.so" name="camera_controller">
        <alwaysOn>true</alwaysOn>
        <updateRate>10</updateRate>
        <cameraName>/robot/line_sensor/right_second</cameraName>
        <imageTopicName>image_raw</imageTopicName>
        <cameraInfoTopicName>camera_info</cameraInfoTopicName>
        <frameName>camera_link</frameName>
        <hackBaseline>0.07</hackBaseline>
        <distortionK1>0.0</distortionK1>
        <distortionK2>0.0</distortionK2>
        <distortionK3>0.0</distortionK3>
        <distortionT1>0.0</distortionT1>
        <distortionT2>0.0</distortionT2>
      </plugin>
    </sensor>
  </gazebo>
  <link name="left_side_second_line_sensor_from_middle">
    <inertial>
      <mass value="0.001"/>
      <inertia ixx="1.5416666666666668e-09" ixy="0.0" ixz="0.0" iyy="1.2083333333333334e-09" iyz="0.0" izz="7.083333333333333e-10"/>
    </inertial>
    <collision name="collision">
      <geometry>
        <box size="0.0015 0.0035 0.0025"/>
      </geometry>
    </collision>
    <visual name="visual">
      <geometry>
        <box size="0.0015 0.0035 0.0025"/>
      </geometry>
    </visual>
  </link>
  <joint name="left_side_second_line_sensor_from_middle_to_base" type="fixed">
    <origin rpy="0 1.5707 0" xyz="0.0935 0.015 0.0044"/>
    <child link="left_side_second_line_sensor_from_middle"/>
    <parent link="base_with_casters"/>
  </joint>
  <gazebo reference="left_side_second_line_sensor_from_middle">
    <sensor name="line_sensor_camera4" type="camera">
      <update_rate>10</update_rate>
      <pose>0 0 0 0 1.571 0</pose>
      <camera name="head">
        <horizontal_fov>0.4</horizontal_fov>
        <image>
          <width>16</width>
          <height>16</height>
          <format>L8</format>
        </image>
        <clip>
          <near>0.001</near>
          <far>0.031</far>
        </clip>
      </camera>
      <always_on>1</always_on>
      <update_rate>10</update_rate>
      <visualize>false</visualize>
      <plugin filename="libgazebo_ros_camera.so" name="camera_controller">
        <alwaysOn>true</alwaysOn>
        <updateRate>10</updateRate>
        <cameraName>/robot/line_sensor/left_second</cameraName>
        <imageTopicName>image_raw</imageTopicName>
        <cameraInfoTopicName>camera_info</cameraInfoTopicName>
        <frameName>camera_link</frameName>
        <hackBaseline>0.07</hackBaseline>
        <distortionK1>0.0</distortionK1>
        <distortionK2>0.0</distortionK2>
        <distortionK3>0.0</distortionK3>
        <distortionT1>0.0</distortionT1>
        <distortionT2>0.0</distortionT2>
      </plugin>
    </sensor>
  </gazebo>
  <link name="right_side_third_line_sensor_from_middle">
    <inertial>
      <mass value="0.001"/>
      <inertia ixx="1.5416666666666668e-09" ixy="0.0" ixz="0.0" iyy="1.2083333333333334e-09" iyz="0.0" izz="7.083333333333333e-10"/>
    </inertial>
    <collision name="collision">
      <geometry>
        <box size="0.0015 0.0035 0.0025"/>
      </geometry>
    </collision>
    <visual name="visual">
      <geometry>
        <box size="0.0015 0.0035 0.0025"/>
      </geometry>
    </visual>
  </link>
  <joint name="right_side_third_line_sensor_from_middle_to_base" type="fixed">
    <origin rpy="0 1.5707 0" xyz="0.0855 -0.035 0.0044"/>
    <child link="right_side_third_line_sensor_from_middle"/>
    <parent link="base_with_casters"/>
  </joint>
  <gazebo reference="right_side_third_line_sensor_from_middle">
    <sensor name="line_sensor_camera5" type="camera">
      <update_rate>10</update_rate>
      <pose>0 0 0 0 1.571 0</pose>
      <camera name="head">
        <horizontal_fov>0.4</horizontal_fov>
        <image>
          <width>16</width>
          <height>16</height>
          <format>L8</format>
        </image>
        <clip>
          <near>0.001</near>
          <far>0.031</far>
        </clip>
      </camera>
      <always_on>1</always_on>
      <update_rate>10</update_rate>
      <visualize>false</visualize>
      <plugin filename="libgazebo_ros_camera.so" name="camera_controller">
        <alwaysOn>true</alwaysOn>
        <updateRate>10</updateRate>
        <cameraName>/robot/line_sensor/right_third</cameraName>
        <imageTopicName>image_raw</imageTopicName>
        <cameraInfoTopicName>camera_info</cameraInfoTopicName>
        <frameName>camera_link</frameName>
        <hackBaseline>0.07</hackBaseline>
        <distortionK1>0.0</distortionK1>
        <distortionK2>0.0</distortionK2>
        <distortionK3>0.0</distortionK3>
        <distortionT1>0.0</distortionT1>
        <distortionT2>0.0</distortionT2>
      </plugin>
    </sensor>
  </gazebo>
  <link name="left_side_third_line_sensor_from_middle">
    <inertial>
      <mass value="0.001"/>
      <inertia ixx="1.5416666666666668e-09" ixy="0.0" ixz="0.0" iyy="1.2083333333333334e-09" iyz="0.0" izz="7.083333333333333e-10"/>
    </inertial>
    <collision name="collision">
      <geometry>
        <box size="0.0015 0.0035 0.0025"/>
      </geometry>
    </collision>
    <visual name="visual">
      <geometry>
        <box size="0.0015 0.0035 0.0025"/>
      </geometry>
    </visual>
  </link>
  <joint name="left_side_third_line_sensor_from_middle_to_base" type="fixed">
    <origin rpy="0 1.5707 0" xyz="0.0855 0.035 0.0044"/>
    <child link="left_side_third_line_sensor_from_middle"/>
    <parent link="base_with_casters"/>
  </joint>
  <gazebo reference="left_side_third_line_sensor_from_middle">
    <sensor name="line_sensor_camera6" type="camera">
      <update_rate>10</update_rate>
      <pose>0 0 0 0 1.571 0</pose>
      <camera name="head">
        <horizontal_fov>0.4</horizontal_fov>
        <image>
          <width>16</width>
          <height>16</height>
          <format>L8</format>
        </image>
        <clip>
          <near>0.001</near>
          <far>0.031</far>
        </clip>
      </camera>
      <always_on>1</always_on>
      <update_rate>10</update_rate>
      <visualize>false</visualize>
      <plugin filename="libgazebo_ros_camera.so" name="camera_controller">
        <alwaysOn>true</alwaysOn>
        <updateRate>10</updateRate>
        <cameraName>/robot/line_sensor/left_third</cameraName>
        <imageTopicName>image_raw</imageTopicName>
        <cameraInfoTopicName>camera_info</cameraInfoTopicName>
        <frameName>camera_link</frameName>
        <hackBaseline>0.07</hackBaseline>
        <distortionK1>0.0</distortionK1>
        <distortionK2>0.0</distortionK2>
        <distortionK3>0.0</distortionK3>
        <distortionT1>0.0</distortionT1>
        <distortionT2>0.0</distortionT2>
      </plugin>
    </sensor>
  </gazebo>
  <link name="camera_stand_pole">
    <inertial>
      <mass value="0.001"/>
      <inertia ixx="1.602530735008333e-07" ixy="0.0" ixz="0.0" iyy="1.602530735008333e-07" iyz="0.0" izz="7.303842e-09"/>
    </inertial>
    <collision name="collision">
      <geometry>
        <cylinder length="0.0433499" radius="0.003822"/>
      </geometry>
    </collision>
    <visual name="visual">
      <geometry>
        <cylinder length="0.0433499" radius="0.003822"/>
      </geometry>
    </visual>
  </link>
  <joint name="camera_stand_pole_to_base" type="fixed">
    <origin rpy="0 1.5707 1.5707" xyz="0.05790475 0 0.1135341"/>
    <child link="camera_stand_pole"/>
    <parent link="base_with_casters"/>
  </joint>
  <!--REVOLUTE CAMERA???, uncomment this and delete the above
    <joint type="revolute" name="camera_stand_pole_to_base">
      <pose>0 0 0 0 0 0</pose>
      <child>camera_stand_pole</child>
      <parent>base</parent>
      <axis>
        <xyz>0 1 0</xyz>
      </axis>
    </joint>
    -->
  <link name="pi_camera">
    <inertial>
      <mass value="0.001"/>
      <inertia ixx="7.208333333333334e-08" ixy="0.0" ixz="0.0" iyy="7.208333333333334e-08" iyz="0.0" izz="9.6e-08"/>
    </inertial>
    <collision name="collision">
      <geometry>
        <box size="0.017 0.024 0.024"/>
      </geometry>
    </collision>
    <visual name="visual">
      <geometry>
        <box size="0.017 0.024 0.024"/>
      </geometry>
    </visual>
  </link>
  <joint name="pi_camera_to_pole" type="fixed">
    <origin rpy="1.5708 0 -1.1707" xyz="0. -0.0104 0"/>
    <child link="pi_camera"/>
    <parent link="camera_stand_pole"/>
  </joint>
  <gazebo reference="pi_camera">
    <sensor name="camera" type="camera">
      <update_rate>10</update_rate>
      <always_on>1</always_on>
      <visualize>false</visualize>
      <camera name="head">
        <horizontal_fov>1.09</horizontal_fov>
        <image>
          <width>1080</width>
          <height>1080</height>
          <format>B8G8R8</format>
        </image>
        <clip>
          <near>0.02</near>
          <far>300</far>
        </clip>
      </camera>
      <plugin filename="libgazebo_ros_camera.so" name="camera_controller">
        <alwaysOn>true</alwaysOn>
        <updateRate>10</updateRate>
        <cameraName>robot/camera</cameraName>
        <imageTopicName>image_raw</imageTopicName>
        <cameraInfoTopicName>camera_info</cameraInfoTopicName>
        <frameName>camera_link</frameName>
        <hackBaseline>0.07</hackBaseline>
        <distortionK1>0.0</distortionK1>
        <distortionK2>0.0</distortionK2>
        <distortionK3>0.0</distortionK3>
        <distortionT1>0.0</distortionT1>
        <distortionT2>0.0</distortionT2>
      </plugin>
    </sensor>
  </gazebo>
  <link name="right_wheel">
    <inertial>
      <mass value="1"/>
      <inertia ixx="6.299999999999999e-05" ixy="0.0" ixz="0.0" iyy="6.299999999999999e-05" iyz="0.0" izz="0.0001125"/>
    </inertial>
    <visual name="right_wheel_visual">
      <origin rpy="0 0 0" xyz="0 0 0"/>
      <geometry>
        <cylinder length="0.009" radius="0.015"/>
      </geometry>
    </visual>
    <collision name="right_wheel_collision">
      <origin rpy="0 0 0" xyz="0 0 0"/>
      <geometry>
        <cylinder length="0.009" radius="0.015"/>
      </geometry>
    </collision>
  </link>
  <gazebo reference="right_wheel">
    <mu1 value="1.0"/>
    <mu2 value="1.0"/>
    <kp value="10000000.0"/>
    <kd value="1.0"/>
    <fdir1 value="1 0 0"/>
  </gazebo>
  <joint name="right_wheel_hinge" type="continuous">
    <origin rpy="0 1.5707 1.5707" xyz="0 -0.0655 0"/>
    <child link="right_wheel"/>
    <parent link="wheel_joint"/>
    <!--proovisin erinevaid väärtusi siia "limit" alla, midagi ei muutunud -->
    <limit effort="10.0" velocity="1.0"/>
    <axis rpy="0 0 0" xyz="0 0 1"/>
  </joint>
  <link name="left_wheel">
    <inertial>
      <mass value="1"/>
      <inertia ixx="6.299999999999999e-05" ixy="0.0" ixz="0.0" iyy="6.299999999999999e-05" iyz="0.0" izz="0.0001125"/>
    </inertial>
    <visual name="left_wheel_visual">
      <origin rpy="0 0 0" xyz="0 0 0"/>
      <geometry>
        <cylinder length="0.009" radius="0.015"/>
      </geometry>
    </visual>
    <collision name="left_wheel_collision">
      <origin rpy="0 0 0" xyz="0 0 0"/>
      <geometry>
        <cylinder length="0.009" radius="0.015"/>
      </geometry>
    </collision>
  </link>
  <gazebo reference="left_wheel">
    <mu1 value="1.0"/>
    <mu2 value="1.0"/>
    <kp value="10000000.0"/>
    <kd value="1.0"/>
    <fdir1 value="1 0 0"/>
  </gazebo>
  <joint name="left_wheel_hinge" type="continuous">
    <origin rpy="0 1.5707 1.5707" xyz="0 0.0655 0"/>
    <child link="left_wheel"/>
    <parent link="wheel_joint"/>
    <limit effort="10.0" velocity="1.0"/>
    <axis rpy="0 0 0" xyz="0 0 1"/>
  </joint>
  <gazebo>
    <plugin filename="libwheel_plugin.so" name="wheel_plugin"/>
  </gazebo>
  <link name="grabber_to_base_1">
    <inertial>
      <mass value="0.001"/>
      <inertia ixx="0.0000337" ixy="0.0" ixz="0.0" iyy="0.0000493" iyz="0.0" izz="0.0000248"/>
    </inertial>
    <collision name="arm_to_base_col">
      <geometry>
        <box size=".006 .034 .03455"/>
      </geometry>
    </collision>
    <visual name="arm_to_base_vis">
      <geometry>
        <box size=".006 .034 .03455"/>
      </geometry>
    </visual>
  </link>
  <joint name="grabber_to_base_joint_1" type="fixed">
    <origin rpy="0 0 0" xyz="0.0835 0 0.0235"/>
    <child link="grabber_to_base_1"/>
    <parent link="base_with_casters"/>
  </joint>
  <link name="pole_rotation_reference">
    <inertial>
      <mass value="0.001"/>
      <inertia ixx="0.0000337" ixy="0.0" ixz="0.0" iyy="0.0000493" iyz="0.0" izz="0.0000248"/>
    </inertial>
    <collision name="pole_rotation_reference_col">
      <geometry>
        <box size=".001 .001 .001"/>
      </geometry>
    </collision>
    <visual name="pole_rotation_reference_vis">
      <geometry>
        <box size=".001 .001 .001"/>
      </geometry>
    </visual>
  </link>
  <joint name="pole_rotation_reference_to_base" type="fixed">
    <origin rpy="0 1.5707 1.5707" xyz="0.0875 0 0.04555"/>
    <child link="pole_rotation_reference"/>
    <parent link="base_with_casters"/>
  </joint>
  <link name="grabber_pole_link">
    <inertial>
      <mass value="0.001"/>
      <inertia ixx="0.0000337" ixy="0.0" ixz="0.0" iyy="0.0000493" iyz="0.0" izz="0.0000248"/>
    </inertial>
    <collision name="the_pole_col">
      <geometry>
        <cylinder length=".034" radius=".006"/>
      </geometry>
    </collision>
    <visual name="the_pole_vis">
      <geometry>
        <cylinder length=".034" radius=".006"/>
      </geometry>
    </visual>
  </link>
  <!-- TODO -->
  <joint name="grabber_pole" type="revolute">
    <origin rpy="0 0 0" xyz="0 0 0"/>
    <child link="grabber_pole_link"/>
    <parent link="pole_rotation_reference"/>
    <limit effort="10.0" lower="0.0" upper="1.5" velocity="1.0"/>
    <axis xyz="0 0 1"/>
  </joint>
  <link name="grabber_mount">
    <collision name="arm_collision_left">
      <origin rpy="0 0 0" xyz="0.0144 0.02 0"/>
      <geometry>
        <box size=".035 .006 .011"/>
      </geometry>
    </collision>
    <visual name="arm_visual_left">
      <origin rpy="0 0 0" xyz="0.0144 0.02 0"/>
      <geometry>
        <box size=".035 .006 .011"/>
      </geometry>
    </visual>
    <collision name="arm_collision_right">
      <origin rpy="0 0 0" xyz="0.0144 -0.02 0"/>
      <geometry>
        <box size=".035 .006 .011"/>
      </geometry>
    </collision>
    <visual name="arm_visual_right">
      <origin rpy="0 0 0" xyz="0.0144 -0.02 0"/>
      <geometry>
        <box size=".035 .006 .011"/>
      </geometry>
    </visual>
    <collision name="collision_under">
      <origin rpy="0 0 0" xyz="0.025 0 -0.00855"/>
      <geometry>
        <box size=".015 .042 .0057"/>
      </geometry>
    </collision>
    <visual name="visual_under">
      <origin rpy="0 0 0" xyz="0.025 0 -0.00855"/>
      <geometry>
        <box size=".015 .042 .0057"/>
      </geometry>
    </visual>
    <inertial>
      <mass value="0.001"/>
      <inertia ixx="0.0000337" ixy="0.0" ixz="0.0" iyy="0.0000493" iyz="0.0" izz="0.0000248"/>
    </inertial>
  </link>
  <joint name="grabber_mount_to_pole" type="fixed">
    <origin rpy="1.5707 0 3.1414" xyz="0 0 0"/>
    <child link="grabber_mount"/>
    <parent link="grabber_pole_link"/>
  </joint>
  <link name="grabber_left_arm_joint">
    <collision name="collision_for_left_arm_joint">
      <geometry>
        <cylinder length=".004" radius=".002"/>
      </geometry>
    </collision>
    <visual name="visual_for_left_arm_joint">
      <geometry>
        <cylinder length=".004" radius=".002"/>
      </geometry>
    </visual>
    <inertial>
      <mass value="0.001"/>
      <inertia ixx="0.0000337" ixy="0.0" ixz="0.0" iyy="0.0000493" iyz="0.0" izz="0.0000248"/>
    </inertial>
  </link>
  <!-- TODO -->
  <joint name="grabber_left_arm_joint_to_grabber_mount" type="revolute">
    <origin rpy="0 3.1414 0" xyz="0.025 0.01 -0.01355"/>
    <child link="grabber_left_arm_joint"/>
    <parent link="grabber_mount"/>
    <limit effort="10.0" lower="0.0" upper="0.7" velocity="1.0"/>
    <axis xyz="0 0 1"/>
  </joint>
  <link name="grabber_right_arm_joint">
    <collision name="collision_for_right_arm_joint">
      <geometry>
        <cylinder length=".004" radius=".002"/>
      </geometry>
    </collision>
    <visual name="visual_for_right_arm_joint">
      <geometry>
        <cylinder length=".004" radius=".002"/>
      </geometry>
    </visual>
    <inertial>
      <mass value="0.001"/>
      <inertia ixx="0.0000337" ixy="0.0" ixz="0.0" iyy="0.0000493" iyz="0.0" izz="0.0000248"/>
    </inertial>
  </link>
  <!-- TODO -->
  <joint name="grabber_right_arm_joint_to_grabber_mount" type="revolute">
    <origin rpy="0 3.1414 0" xyz="0.025 -0.01 -0.01355"/>
    <child link="grabber_right_arm_joint"/>
    <parent link="grabber_mount"/>
    <limit effort="10.0" lower="0.0" upper="-0.7" velocity="1.0"/>
    <axis xyz="0 0 1"/>
  </joint>
  <link name="grabber_arm_left">
    <collision name="main_arm_collision_l">
      <origin rpy="0 0 0.78535" xyz="0.023 0.019 0"/>
      <geometry>
        <box size=".06213 .009 .005"/>
      </geometry>
    </collision>
    <visual name="main_arm_visual_l">
      <origin rpy="0 0 0.78535" xyz="0.023 0.019 0"/>
      <geometry>
        <box size=".06213 .009 .005"/>
      </geometry>
    </visual>
    <collision name="small_arm_collision_l_f">
      <origin rpy="0 0 0" xyz="0.061 0.037 -0.0025"/>
      <geometry>
        <box size=".029 .003 .002"/>
      </geometry>
    </collision>
    <visual name="small_arm_visual_l_f">
      <origin rpy="0 0 0" xyz="0.061 0.037 -0.0025"/>
      <geometry>
        <box size=".029 .003 .002"/>
      </geometry>
    </visual>
    <collision name="small_arm_collision_l_b">
      <origin rpy="0 0 -1.5707" xyz="0.0465 0.0225 -0.0025"/>
      <geometry>
        <box size=".029 .003 .002"/>
      </geometry>
    </collision>
    <visual name="small_arm_visual_l_b">
      <origin rpy="0 0 -1.5707" xyz="0.0465 0.0225 -0.0025"/>
      <geometry>
        <box size=".029 .003 .002"/>
      </geometry>
    </visual>
    <inertial>
      <mass value="0.001"/>
      <inertia ixx="0.0000337" ixy="0.0" ixz="0.0" iyy="0.0000493" iyz="0.0" izz="0.0000248"/>
    </inertial>
  </link>
  <joint name="grabber_arm_left_to_grabber_joint" type="fixed">
    <origin rpy="0 3.1414 0" xyz="0 0 0"/>
    <child link="grabber_arm_left"/>
    <parent link="grabber_left_arm_joint"/>
  </joint>
  <link name="grabber_arm_right">
    <collision name="main_arm_collision_r">
      <origin rpy="0 0 -0.78535" xyz="0.023 -0.019 0"/>
      <geometry>
        <box size=".06213 .009 .005"/>
      </geometry>
    </collision>
    <visual name="main_arm_visual_r">
      <origin rpy="0 0 -0.78535" xyz="0.023 -0.019 0"/>
      <geometry>
        <box size=".06213 .009 .005"/>
      </geometry>
    </visual>
    <collision name="small_arm_collision_r_f">
      <origin rpy="0 0 0" xyz="0.061 -0.037 -0.0025"/>
      <geometry>
        <box size=".029 .003 .002"/>
      </geometry>
    </collision>
    <visual name="small_arm_visual_r_f">
      <origin rpy="0 0 0" xyz="0.061 -0.037 -0.0025"/>
      <geometry>
        <box size=".029 .003 .002"/>
      </geometry>
    </visual>
    <collision name="small_arm_collision_r_b">
      <origin rpy="0 0 -1.5707" xyz="0.0465 -0.0225 -0.0025"/>
      <geometry>
        <box size=".029 .003 .002"/>
      </geometry>
    </collision>
    <visual name="small_arm_visual_r_b">
      <origin rpy="0 0 -1.5707" xyz="0.0465 -0.0225 -0.0025"/>
      <geometry>
        <box size=".029 .003 .002"/>
      </geometry>
    </visual>
    <inertial>
      <mass value="0.001"/>
      <inertia ixx="0.0000337" ixy="0.0" ixz="0.0" iyy="0.0000493" iyz="0.0" izz="0.0000248"/>
    </inertial>
  </link>
  <joint name="grabber_arm_right_to_grabber_joint" type="fixed">
    <origin rpy="0 3.1414 0" xyz="0 0 0"/>
    <child link="grabber_arm_right"/>
    <parent link="grabber_right_arm_joint"/>
  </joint>
  <gazebo>
    <plugin filename="libgrabber_plugin.so" name="grabber_plugin"/>
  </gazebo>
</robot>
